Workbook

Sheet 1. Raw Data
A1: employee_id | B1: age | C1: department | D1: job_level | E1: education_field | F1: tenure_years | G1: monthly_income | H1: overtime | I1: job_satisfaction | J1: worklife_balance | K1: distance_from_home_km | L1: years_since_last_promotion | M1: trainings_last_year | N1: attrition | P1: Highlighted cells = data quality issues fixed in the next tab
A2: EMP-0001 | B2: 47 | C2: Engineering | D2: Junior | E2: Business | F2: 11.4 | G2: 3323.12 | H2: No | I2: 1 | J2: 2 | K2: 5 | L2: 2 | M2: 2 | N2: Yes
A3: EMP-0002 | B3: 30 | C3: Sales | D3: Mid | E3: Marketing | F3: 7.2 | G3: 4438.49 | H3: No | I3: 4 | J3: 1 | K3: 7 | L3: 5 | M3: 1 | N3: No
A4: EMP-0003 | B4: 34 | C4: Customer Support | D4: Senior | E4: Technical | F4: 4.2 | G4: 7805.91 | H4: Yes | I4: 2 | J4: 3 | K4: 3 | L4: 1 | M4: 3 | N4: No
A5: EMP-0004 | B5: 25 | C5: Sales | D5: Mid | E5: Business | F5: 1 | G5: 4840.78 | H5: Yes | I5: 3 | J5: 3 | K5: 4 | L5: 1 | M5: 2 | N5: No
A6: EMP-0005 | B6: 21 | C6: Sales | D6: Mid | E6: Business | F6: 0 | G6: 4958.48 | H6: No | I6: 1 | J6: 1 | K6: 9 | L6: 0 | M6: 3 | N6: Yes
A7: EMP-0006 | B7: 21 | C7: Finance | D7: Junior | E7: Technical | F7: 0 | G7: 2983.33 | H7: No | I7: 4 | J7: 4 | K7: 5 | L7: 0 | M7: 0 | N7: No
A8: EMP-0007 | B8: 47 | C8: Customer Support | D8: Mid | E8: Business | F8: 2 | G8: 4309.95 | H8: Yes | I8: 3 | J8: 2 | K8: 1 | L8: 1 | M8: 4 | N8: No
A9: EMP-0008 | B9: 31 | C9: Customer Support | D9: Mid | E9: Technical | F9: 6.5 | G9: 5213.86 | H9: No | I9: 4 | J9: 1 | K9: 16 | L9: 0 | M9: 3 | N9: No
A10: EMP-0009 | B10: 32 | C10: Sales | D10: Senior | E10: Marketing | F10: 5 | G10: 7197.82 | H10: No | I10: 4 | J10: 4 | K10: 11 | L10: 0 | M10: 2 | N10: No
A11: EMP-0010 | B11: 29 | C11: Engineering | D11: Mid | E11: Marketing | F11: 2.8 | G11: 5471.8 | H11: No | I11: 2 | J11: 2 | K11: 8 | L11: 0 | M11: 1 | N11: Yes
A12: EMP-0011 | B12: 37 | C12: Customer Support | D12: Mid | E12: Business | F12: 0.1 | G12: 4974.84 | H12: No | I12: 4 | J12: 2 | K12: 1 | L12: 0 | M12: 2 | N12: No
A13: EMP-0012 | B13: 37 | C13: Customer Support | D13: Mid | E13: Marketing | F13: 5.6 | G13: 4362.7 | H13: No | I13: 4 | J13: 3 | K13: 1 | L13: 0 | M13: 2 | N13: Yes
... A136: EMP-0135 | B136: 38 | C136: Marketing | D136: Junior | E136: Technical | F136: 0.5 | G136: 3647.98 | H136: No | I136: 1 | J136: 4 | K136: 7 | L136: 0 | M136: 4 | N136: No
A137: EMP-0136 | B137: 35 | C137: Marketing | D137: Junior | E137: Technical | F137: 10.4 | H137: No | I137: 2 | J137: 2 | K137: 7 | L137: 0 | M137: 2 | N137: No
A138: EMP-0137 | B138: 21 | C138: Engineering | D138: Junior | E138: Business | F138: 0 | G138: 3340.46 | H138: No | I138: 2 | J138: 4 | K138: 1 | L138: 0 | M138: 3 | N138: No
A139: EMP-0138 | B139: 35 | C139: Finance | D139: Junior | E139: Marketing | F139: 9 | G139: 3226.19 | H139: No | I139: 3 | J139: 4 | K139: 1 | L139: 2 | M139: 3 | N139: No
A140: EMP-0139 | B140: 34 | C140: Engineering | D140: Junior | E140: Other | F140: 1.4 | G140: 3328.93 | H140: Yes | I140: 1 | J140: 1 | K140: 8 | L140: 0 | M140: 2 | N140: Yes
A141: EMP-0140 | B141: 31 | C141: Marketing | D141: Mid | E141: Marketing | F141: 1.6 | G141: 5385.84 | H141: No | I141: 2 | J141: 4 | K141: 1 | L141: 1 | M141: 3 | N141: No
A142: EMP-0141 | B142: 28 | C142: Customer Support | D142: Mid | E142: Business | F142: 6.1 | G142: 5732.86 | H142: Yes | I142: 3 | J142: 3 | K142: 12 | L142: 3 | M142: 3 | N142: No
A143: EMP-0142 | B143: 31 | C143: Engineering | D143: Junior | E143: Other | F143: 3.7 | G143: 3059.05 | H143: No | I143: 3 | J143: 3 | K143: 1 | L143: 2 | M143: 2 | N143: No
A144: EMP-0143 | B144: 38 | C144: Sales | D144: Mid | E144: Marketing | F144: 1.5 | G144: 5635.63 | H144: Yes | I144: 2 | J144: 3 | K144: 1 | L144: 0 | M144: 3 | N144: Yes
A145: EMP-0144 | B145: 33 | C145: Marketing | D145: Mid | E145: Technical | F145: 6.7 | G145: 5053.82 | H145: Yes | I145: 3 | J145: 2 | K145: 1 | L145: 1 | M145: 0 | N145: Yes
A146: EMP-0145 | B146: 24 | C146: Sales | D146: Senior | E146: Technical | F146: 1.1 | G146: 7216.61 | H146: Yes | I146: 2 | J146: 2 | K146: 22 | L146: 0 | M146: 5 | N146: Yes
A147: EMP-0146 | B147: 32 | C147: Engineering | D147: Junior | E147: Other | F147: 2.8 | G147: 3226.7 | H147: No | I147: 2 | J147: 3 | K147: 1 | L147: 0 | M147: 1 | N147: No
A148: EMP-0147 | B148: 29 | C148: Sales | D148: Junior | E148: Technical | F148: 3.7 | G148: 3730.34 | H148: No | I148: 3 | J148: 3 | K148: 4 | L148: 1 | M148: 2 | N148: No
A149: EMP-0148 | B149: 39 | C149: Sales | D149: Senior | E149: Business | F149: 2.7 | G149: 6848.28 | H149: No | I149: 2 | J149: 3 | K149: 6 | L149: 0 | M149: 2 | N149: No
... A190: EMP-0189 | B190: 38 | C190: HR | D190: Senior | E190: Marketing | F190: 6.1 | G190: 7952.13 | H190: No | I190: 2 | J190: 3 | K190: 8 | L190: 0 | M190: 4 | N190: Yes
A191: EMP-0190 | B191: 27 | C191: Engineering | D191: Junior | E191: Other | F191: 0.3 | H191: Yes | I191: 3 | J191: 2 | K191: 20 | L191: 0 | M191: 3 | N191: No
A192: EMP-0191 | B192: 25 | C192: Marketing | D192: Mid | E192: Marketing | F192: 4 | H192: No | I192: 2 | J192: 3 | K192: 1 | L192: 0 | M192: 2 | N192: No
A193: EMP-0192 | B193: 31 | C193: Marketing | D193: Senior | E193: Business | F193: 2.2 | G193: 7787.1 | H193: Yes | I193: 3 | J193: 3 | K193: 2 | L193: 0 | M193: 3 | N193: No
A194: EMP-0193 | B194: 46 | C194: Engineering | D194: Junior | E194: Marketing | F194: 9.8 | G194: 3645.19 | H194: Yes | I194: 2 | J194: 1 | K194: 1 | L194: 1 | M194: 1 | N194: No
A195: EMP-0194 | B195: 42 | C195: Customer Support | D195: Junior | E195: Marketing | F195: 7.6 | G195: 3644.27 | H195: Yes | I195: 2 | J195: 1 | K195: 4 | L195: 5 | M195: 2 | N195: Yes
A196: EMP-0195 | B196: 29 | C196: Engineering | D196: Junior | E196: Marketing | F196: 1.2 | G196: 3546.51 | H196: Yes | I196: 1 | J196: 3 | K196: 4 | L196: 0 | M196: 2 | N196: Yes
A197: EMP-0196 | B197: 41 | C197: Finance | D197: Mid | E197: Business | F197: 4.6 | G197: 5501.18 | H197: No | I197: 4 | J197: 2 | K197: 4 | L197: 3 | M197: 3 | N197: No
A198: EMP-0197 | B198: 40 | C198: Finance | D198: Mid | E198: Technical | F198: 0.2 | G198: 4509.16 | H198: No | I198: 3 | J198: 3 | K198: 2 | L198: 0 | M198: 1 | N198: No
A199: EMP-0198 | B199: 40 | C199: HR | D199: Junior | E199: Other | F199: 2.4 | G199: 3306.38 | H199: No | I199: 3 | J199: 3 | K199: 16 | L199: 2 | M199: 2 | N199: No
A200: EMP-0199 | B200: 31 | C200: Engineering | D200: Senior | E200: Marketing | F200: 5.8 | G200: 7892.16 | H200: No | I200: 1 | J200: 1 | K200: 9 | L200: 1 | M200: 1 | N200: Yes
A201: EMP-0200 | B201: 21 | C201: Customer Support | D201: Senior | E201: Technical | F201: 0 | G201: 7033.25 | H201: No | I201: 2 | J201: 3 | K201: 1 | L201: 0 | M201: 1 | N201: No
A202: EMP-0201 | B202: 27 | C202: Sales | D202: Mid | E202: Marketing | F202: 0.5 | G202: 4421.59 | H202: Yes | I202: 2 | J202: 3 | K202: 2 | L202: 0 | M202: 0 | N202: No
...

Sheet 2. Cleaned Data
A1: Cleaning applied: (1) overtime standardised to Yes/No, (2) missing income filled with department+level average
A2: employee_id | B2: age | C2: department | D2: job_level | E2: education_field | F2: tenure_years | G2: monthly_income | H2: overtime | I2: job_satisfaction | J2: worklife_balance | K2: distance_from_home_km | L2: years_since_last_promotion | M2: trainings_last_year | N2: attrition
A3: ='1. Raw Data'!A2 -> EMP-0001 | B3: ='1. Raw Data'!B2 -> 47 | C3: ='1. Raw Data'!C2 -> Engineering | D3: ='1. Raw Data'!D2 -> Junior | E3: ='1. Raw Data'!E2 -> Business | F3: ='1. Raw Data'!F2 -> 11.4 | G3: =IF('1. Raw Data'!G2="",ROUND(IFERROR(AVERAGEIFS('1. Raw Data'!G2:G1201,'1. Raw Data'!C2:C1201,'1. Raw Data'!C2,'1. Raw Data'!D2:D1201,'1. Raw Data'!D2),0),2),'1. Raw Data'!G2) -> 3323.12 | H3: =PROPER('1. Raw Data'!H2) -> No | I3: ='1. Raw Data'!I2 -> 1 | J3: ='1. Raw Data'!J2 -> 2 | K3: ='1. Raw Data'!K2 -> 5 | L3: ='1. Raw Data'!L2 -> 2 | M3: ='1. Raw Data'!M2 -> 2 | N3: ='1. Raw Data'!N2 -> Yes
A4: ='1. Raw Data'!A3 -> EMP-0002 | B4: ='1. Raw Data'!B3 -> 30 | C4: ='1. Raw Data'!C3 -> Sales | D4: ='1. Raw Data'!D3 -> Mid | E4: ='1. Raw Data'!E3 -> Marketing | F4: ='1. Raw Data'!F3 -> 7.2 | G4: =IF('1. Raw Data'!G3="",ROUND(IFERROR(AVERAGEIFS('1. Raw Data'!G2:G1201,'1. Raw Data'!C2:C1201,'1. Raw Data'!C3,'1. Raw Data'!D2:D1201,'1. Raw Data'!D3),0),2),'1. Raw Data'!G3) -> 4438.49 | H4: =PROPER('1. Raw Data'!H3) -> No | I4: ='1. Raw Data'!I3 -> 4 | J4: ='1. Raw Data'!J3 -> 1 | K4: ='1. Raw Data'!K3 -> 7 | L4: ='1. Raw Data'!L3 -> 5 | M4: ='1. Raw Data'!M3 -> 1 | N4: ='1. Raw Data'!N3 -> No
A5: ='1. Raw Data'!A4 -> EMP-0003 | B5: ='1. Raw Data'!B4 -> 34 | C5: ='1. Raw Data'!C4 -> Customer Support | D5: ='1. Raw Data'!D4 -> Senior | E5: ='1. Raw Data'!E4 -> Technical | F5: ='1. Raw Data'!F4 -> 4.2 | G5: =IF('1. Raw Data'!G4="",ROUND(IFERROR(AVERAGEIFS('1. Raw Data'!G2:G1201,'1. Raw Data'!C2:C1201,'1. Raw Data'!C4,'1. Raw Data'!D2:D1201,'1. Raw Data'!D4),0),2),'1. Raw Data'!G4) -> 7805.91 | H5: =PROPER('1. Raw Data'!H4) -> Yes | I5: ='1. Raw Data'!I4 -> 2 | J5: ='1. Raw Data'!J4 -> 3 | K5: ='1. Raw Data'!K4 -> 3 | L5: ='1. Raw Data'!L4 -> 1 | M5: ='1. Raw Data'!M4 -> 3 | N5: ='1. Raw Data'!N4 -> No
A6: ='1. Raw Data'!A5 -> EMP-0004 | B6: ='1. Raw Data'!B5 -> 25 | C6: ='1. Raw Data'!C5 -> Sales | D6: ='1. Raw Data'!D5 -> Mid | E6: ='1. Raw Data'!E5 -> Business | F6: ='1. Raw Data'!F5 -> 1 | G6: =IF('1. Raw Data'!G5="",ROUND(IFERROR(AVERAGEIFS('1. Raw Data'!G2:G1201,'1. Raw Data'!C2:C1201,'1. Raw Data'!C5,'1. Raw Data'!D2:D1201,'1. Raw Data'!D5),0),2),'1. Raw Data'!G5) -> 4840.78 | H6: =PROPER('1. Raw Data'!H5) -> Yes | I6: ='1. Raw Data'!I5 -> 3 | J6: ='1. Raw Data'!J5 -> 3 | K6: ='1. Raw Data'!K5 -> 4 | L6: ='1. Raw Data'!L5 -> 1 | M6: ='1. Raw Data'!M5 -> 2 | N6: ='1. Raw Data'!N5 -> No
A7: ='1. Raw Data'!A6 -> EMP-0005 | B7: ='1. Raw Data'!B6 -> 21 | C7: ='1. Raw Data'!C6 -> Sales | D7: ='1. Raw Data'!D6 -> Mid | E7: ='1. Raw Data'!E6 -> Business | F7: ='1. Raw Data'!F6 -> 0 | G7: =IF('1. Raw Data'!G6="",ROUND(IFERROR(AVERAGEIFS('1. Raw Data'!G2:G1201,'1. Raw Data'!C2:C1201,'1. Raw Data'!C6,'1. Raw Data'!D2:D1201,'1. Raw Data'!D6),0),2),'1. Raw Data'!G6) -> 4958.48 | H7: =PROPER('1. Raw Data'!H6) -> No | I7: ='1. Raw Data'!I6 -> 1 | J7: ='1. Raw Data'!J6 -> 1 | K7: ='1. Raw Data'!K6 -> 9 | L7: ='1. Raw Data'!L6 -> 0 | M7: ='1. Raw Data'!M6 -> 3 | N7: ='1. Raw Data'!N6 -> Yes
A8: ='1. Raw Data'!A7 -> EMP-0006 | B8: ='1. Raw Data'!B7 -> 21 | C8: ='1. Raw Data'!C7 -> Finance | D8: ='1. Raw Data'!D7 -> Junior | E8: ='1. Raw Data'!E7 -> Technical | F8: ='1. Raw Data'!F7 -> 0 | G8: =IF('1. Raw Data'!G7="",ROUND(IFERROR(AVERAGEIFS('1. Raw Data'!G2:G1201,'1. Raw Data'!C2:C1201,'1. Raw Data'!C7,'1. Raw Data'!D2:D1201,'1. Raw Data'!D7),0),2),'1. Raw Data'!G7) -> 2983.33 | H8: =PROPER('1. Raw Data'!H7) -> No | I8: ='1. Raw Data'!I7 -> 4 | J8: ='1. Raw Data'!J7 -> 4 | K8: ='1. Raw Data'!K7 -> 5 | L8: ='1. Raw Data'!L7 -> 0 | M8: ='1. Raw Data'!M7 -> 0 | N8: ='1. Raw Data'!N7 -> No
A9: ='1. Raw Data'!A8 -> EMP-0007 | B9: ='1. Raw Data'!B8 -> 47 | C9: ='1. Raw Data'!C8 -> Customer Support | D9: ='1. Raw Data'!D8 -> Mid | E9: ='1. Raw Data'!E8 -> Business | F9: ='1. Raw Data'!F8 -> 2 | G9: =IF('1. Raw Data'!G8="",ROUND(IFERROR(AVERAGEIFS('1. Raw Data'!G2:G1201,'1. Raw Data'!C2:C1201,'1. Raw Data'!C8,'1. Raw Data'!D2:D1201,'1. Raw Data'!D8),0),2),'1. Raw Data'!G8) -> 4309.95 | H9: =PROPER('1. Raw Data'!H8) -> Yes | I9: ='1. Raw Data'!I8 -> 3 | J9: ='1. Raw Data'!J8 -> 2 | K9: ='1. Raw Data'!K8 -> 1 | L9: ='1. Raw Data'!L8 -> 1 | M9: ='1. Raw Data'!M8 -> 4 | N9: ='1. Raw Data'!N8 -> No
A10: ='1. Raw Data'!A9 -> EMP-0008 | B10: ='1. Raw Data'!B9 -> 31 | C10: ='1. Raw Data'!C9 -> Customer Support | D10: ='1. Raw Data'!D9 -> Mid | E10: ='1. Raw Data'!E9 -> Technical | F10: ='1. Raw Data'!F9 -> 6.5 | G10: =IF('1. Raw Data'!G9="",ROUND(IFERROR(AVERAGEIFS('1. Raw Data'!G2:G1201,'1. Raw Data'!C2:C1201,'1. Raw Data'!C9,'1. Raw Data'!D2:D1201,'1. Raw Data'!D9),0),2),'1. Raw Data'!G9) -> 5213.86 | H10: =PROPER('1. Raw Data'!H9) -> No | I10: ='1. Raw Data'!I9 -> 4 | J10: ='1. Raw Data'!J9 -> 1 | K10: ='1. Raw Data'!K9 -> 16 | L10: ='1. Raw Data'!L9 -> 0 | M10: ='1. Raw Data'!M9 -> 3 | N10: ='1. Raw Data'!N9 -> No
A11: ='1. Raw Data'!A10 -> EMP-0009 | B11: ='1. Raw Data'!B10 -> 32 | C11: ='1. Raw Data'!C10 -> Sales | D11: ='1. Raw Data'!D10 -> Senior | E11: ='1. Raw Data'!E10 -> Marketing | F11: ='1. Raw Data'!F10 -> 5 | G11: =IF('1. Raw Data'!G10="",ROUND(IFERROR(AVERAGEIFS('1. Raw Data'!G2:G1201,'1. Raw Data'!C2:C1201,'1. Raw Data'!C10,'1. Raw Data'!D2:D1201,'1. Raw Data'!D10),0),2),'1. Raw Data'!G10) -> 7197.82 | H11: =PROPER('1. Raw Data'!H10) -> No | I11: ='1. Raw Data'!I10 -> 4 | J11: ='1. Raw Data'!J10 -> 4 | K11: ='1. Raw Data'!K10 -> 11 | L11: ='1. Raw Data'!L10 -> 0 | M11: ='1. Raw Data'!M10 -> 2 | N11: ='1. Raw Data'!N10 -> No
A12: ='1. Raw Data'!A11 -> EMP-0010 | B12: ='1. Raw Data'!B11 -> 29 | C12: ='1. Raw Data'!C11 -> Engineering | D12: ='1. Raw Data'!D11 -> Mid | E12: ='1. Raw Data'!E11 -> Marketing | F12: ='1. Raw Data'!F11 -> 2.8 | G12: =IF('1. Raw Data'!G11="",ROUND(IFERROR(AVERAGEIFS('1. Raw Data'!G2:G1201,'1. Raw Data'!C2:C1201,'1. Raw Data'!C11,'1. Raw Data'!D2:D1201,'1. Raw Data'!D11),0),2),'1. Raw Data'!G11) -> 5471.8 | H12: =PROPER('1. Raw Data'!H11) -> No | I12: ='1. Raw Data'!I11 -> 2 | J12: ='1. Raw Data'!J11 -> 2 | K12: ='1. Raw Data'!K11 -> 8 | L12: ='1. Raw Data'!L11 -> 0 | M12: ='1. Raw Data'!M11 -> 1 | N12: ='1. Raw Data'!N11 -> Yes
A13: ='1. Raw Data'!A12 -> EMP-0011 | B13: ='1. Raw Data'!B12 -> 37 | C13: ='1. Raw Data'!C12 -> Customer Support | D13: ='1. Raw Data'!D12 -> Mid | E13: ='1. Raw Data'!E12 -> Business | F13: ='1. Raw Data'!F12 -> 0.1 | G13: =IF('1. Raw Data'!G12="",ROUND(IFERROR(AVERAGEIFS('1. Raw Data'!G2:G1201,'1. Raw Data'!C2:C1201,'1. Raw Data'!C12,'1. Raw Data'!D2:D1201,'1. Raw Data'!D12),0),2),'1. Raw Data'!G12) -> 4974.84 | H13: =PROPER('1. Raw Data'!H12) -> No | I13: ='1. Raw Data'!I12 -> 4 | J13: ='1. Raw Data'!J12 -> 2 | K13: ='1. Raw Data'!K12 -> 1 | L13: ='1. Raw Data'!L12 -> 0 | M13: ='1. Raw Data'!M12 -> 2 | N13: ='1. Raw Data'!N12 -> No
A14: ='1. Raw Data'!A13 -> EMP-0012 | B14: ='1. Raw Data'!B13 -> 37 | C14: ='1. Raw Data'!C13 -> Customer Support | D14: ='1. Raw Data'!D13 -> Mid | E14: ='1. Raw Data'!E13 -> Marketing | F14: ='1. Raw Data'!F13 -> 5.6 | G14: =IF('1. Raw Data'!G13="",ROUND(IFERROR(AVERAGEIFS('1. Raw Data'!G2:G1201,'1. Raw Data'!C2:C1201,'1. Raw Data'!C13,'1. Raw Data'!D2:D1201,'1. Raw Data'!D13),0),2),'1. Raw Data'!G13) -> 4362.7 | H14: =PROPER('1. Raw Data'!H13) -> No | I14: ='1. Raw Data'!I13 -> 4 | J14: ='1. Raw Data'!J13 -> 3 | K14: ='1. Raw Data'!K13 -> 1 | L14: ='1. Raw Data'!L13 -> 0 | M14: ='1. Raw Data'!M13 -> 2 | N14: ='1. Raw Data'!N13 -> Yes
A15: ='1. Raw Data'!A14 -> EMP-0013 | B15: ='1. Raw Data'!B14 -> 29 | C15: ='1. Raw Data'!C14 -> Sales | D15: ='1. Raw Data'!D14 -> Senior | E15: ='1. Raw Data'!E14 -> Business | F15: ='1. Raw Data'!F14 -> 0.5 | G15: =IF('1. Raw Data'!G14="",ROUND(IFERROR(AVERAGEIFS('1. Raw Data'!G2:G1201,'1. Raw Data'!C2:C1201,'1. Raw Data'!C14,'1. Raw Data'!D2:D1201,'1. Raw Data'!D14),0),2),'1. Raw Data'!G14) -> 6178.44 | H15: =PROPER('1. Raw Data'!H14) -> No | I15: ='1. Raw Data'!I14 -> 3 | J15: ='1. Raw Data'!J14 -> 3 | K15: ='1. Raw Data'!K14 -> 1 | L15: ='1. Raw Data'!L14 -> 0 | M15: ='1. Raw Data'!M14 -> 3 | N15: ='1. Raw Data'!N14 -> Yes
A16: ='1. Raw Data'!A15 -> EMP-0014 | B16: ='1. Raw Data'!B15 -> 32 | C16: ='1. Raw Data'!C15 -> Customer Support | D16: ='1. Raw Data'!D15 -> Mid | E16: ='1. Raw Data'!E15 -> Other | F16: ='1. Raw Data'!F15 -> 5.3 | G16: =IF('1. Raw Data'!G15="",ROUND(IFERROR(AVERAGEIFS('1. Raw Data'!G2:G1201,'1. Raw Data'!C2:C1201,'1. Raw Data'!C15,'1. Raw Data'!D2:D1201,'1. Raw Data'!D15),0),2),'1. Raw Data'!G15) -> 5636.71 | H16: =PROPER('1. Raw Data'!H15) -> Yes | I16: ='1. Raw Data'!I15 -> 4 | J16: ='1. Raw Data'!J15 -> 4 | K16: ='1. Raw Data'!K15 -> 7 | L16: ='1. Raw Data'!L15 -> 4 | M16: ='1. Raw Data'!M15 -> 0 | N16: ='1. Raw Data'!N15 -> Yes
A17: ='1. Raw Data'!A16 -> EMP-0015 | B17: ='1. Raw Data'!B16 -> 29 | C17: ='1. Raw Data'!C16 -> Finance | D17: ='1. Raw Data'!D16 -> Mid | E17: ='1. Raw Data'!E16 -> Other | F17: ='1. Raw Data'!F16 -> 7.2 | G17: =IF('1. Raw Data'!G16="",ROUND(IFERROR(AVERAGEIFS('1. Raw Data'!G2:G1201,'1. Raw Data'!C2:C1201,'1. Raw Data'!C16,'1. Raw Data'!D2:D1201,'1. Raw Data'!D16),0),2),'1. Raw Data'!G16) -> 4131.14 | H17: =PROPER('1. Raw Data'!H16) -> No | I17: ='1. Raw Data'!I16 -> 1 | J17: ='1. Raw Data'!J16 -> 3 | K17: ='1. Raw Data'!K16 -> 4 | L17: ='1. Raw Data'!L16 -> 0 | M17: ='1. Raw Data'!M16 -> 2 | N17: ='1. Raw Data'!N16 -> No
A18: ='1. Raw Data'!A17 -> EMP-0016 | B18: ='1. Raw Data'!B17 -> 31 | C18: ='1. Raw Data'!C17 -> Engineering | D18: ='1. Raw Data'!D17 -> Junior | E18: ='1. Raw Data'!E17 -> Technical | F18: ='1. Raw Data'!F17 -> 0.5 | G18: =IF('1. Raw Data'!G17="",ROUND(IFERROR(AVERAGEIFS('1. Raw Data'!G2:G1201,'1. Raw Data'!C2:C1201,'1. Raw Data'!C17,'1. Raw Data'!D2:D1201,'1. Raw Data'!D17),0),2),'1. Raw Data'!G17) -> 2935.61 | H18: =PROPER('1. Raw Data'!H17) -> No | I18: ='1. Raw Data'!I17 -> 3 | J18: ='1. Raw Data'!J17 -> 2 | K18: ='1. Raw Data'!K17 -> 20 | L18: ='1. Raw Data'!L17 -> 0 | M18: ='1. Raw Data'!M17 -> 0 | N18: ='1. Raw Data'!N17 -> No
A19: ='1. Raw Data'!A18 -> EMP-0017 | B19: ='1. Raw Data'!B18 -> 31 | C19: ='1. Raw Data'!C18 -> HR | D19: ='1. Raw Data'!D18 -> Junior | E19: ='1. Raw Data'!E18 -> Marketing | F19: ='1. Raw Data'!F18 -> 1 | G19: =IF('1. Raw Data'!G18="",ROUND(IFERROR(AVERAGEIFS('1. Raw Data'!G2:G1201,'1. Raw Data'!C2:C1201,'1. Raw Data'!C18,'1. Raw Data'!D2:D1201,'1. Raw Data'!D18),0),2),'1. Raw Data'!G18) -> 3282.02 | H19: =PROPER('1. Raw Data'!H18) -> No | I19: ='1. Raw Data'!I18 -> 3 | J19: ='1. Raw Data'!J18 -> 3 | K19: ='1. Raw Data'!K18 -> 7 | L19: ='1. Raw Data'!L18 -> 1 | M19: ='1. Raw Data'!M18 -> 0 | N19: ='1. Raw Data'!N18 -> No
A20: ='1. Raw Data'!A19 -> EMP-0018 | B20: ='1. Raw Data'!B19 -> 21 | C20: ='1. Raw Data'!C19 -> Customer Support | D20: ='1. Raw Data'!D19 -> Senior | E20: ='1. Raw Data'!E19 -> Other | F20: ='1. Raw Data'!F19 -> 0 | G20: =IF('1. Raw Data'!G19="",ROUND(IFERROR(AVERAGEIFS('1. Raw Data'!G2:G1201,'1. Raw Data'!C2:C1201,'1. Raw Data'!C19,'1. Raw Data'!D2:D1201,'1. Raw Data'!D19),0),2),'1. Raw Data'!G19) -> 7640.97 | H20: =PROPER('1. Raw Data'!H19) -> Yes | I20: ='1. Raw Data'!I19 -> 3 | J20: ='1. Raw Data'!J19 -> 3 | K20: ='1. Raw Data'!K19 -> 8 | L20: ='1. Raw Data'!L19 -> 0 | M20: ='1. Raw Data'!M19 -> 4 | N20: ='1. Raw Data'!N19 -> No
A21: ='1. Raw Data'!A20 -> EMP-0019 | B21: ='1. Raw Data'!B20 -> 37 | C21: ='1. Raw Data'!C20 -> Engineering | D21: ='1. Raw Data'!D20 -> Lead | E21: ='1. Raw Data'!E20 -> Business | F21: ='1. Raw Data'!F20 -> 4.3 | G21: =IF('1. Raw Data'!G20="",ROUND(IFERROR(AVERAGEIFS('1. Raw Data'!G2:G1201,'1. Raw Data'!C2:C1201,'1. Raw Data'!C20,'1. Raw Data'!D2:D1201,'1. Raw Data'!D20),0),2),'1. Raw Data'!G20) -> 8700.2 | H21: =PROPER('1. Raw Data'!H20) -> No | I21: ='1. Raw Data'!I20 -> 2 | J21: ='1. Raw Data'!J20 -> 3 | K21: ='1. Raw Data'!K20 -> 1 | L21: ='1. Raw Data'!L20 -> 4 | M21: ='1. Raw Data'!M20 -> 2 | N21: ='1. Raw Data'!N20 -> No
A22: ='1. Raw Data'!A21 -> EMP-0020 | B22: ='1. Raw Data'!B21 -> 42 | C22: ='1. Raw Data'!C21 -> Customer Support | D22: ='1. Raw Data'!D21 -> Junior | E22: ='1. Raw Data'!E21 -> Marketing | F22: ='1. Raw Data'!F21 -> 5.1 | G22: =IF('1. Raw Data'!G21="",ROUND(IFERROR(AVERAGEIFS('1. Raw Data'!G2:G1201,'1. Raw Data'!C2:C1201,'1. Raw Data'!C21,'1. Raw Data'!D2:D1201,'1. Raw Data'!D21),0),2),'1. Raw Data'!G21) -> 3425.1 | H22: =PROPER('1. Raw Data'!H21) -> Yes | I22: ='1. Raw Data'!I21 -> 4 | J22: ='1. Raw Data'!J21 -> 2 | K22: ='1. Raw Data'!K21 -> 14 | L22: ='1. Raw Data'!L21 -> 1 | M22: ='1. Raw Data'!M21 -> 2 | N22: ='1. Raw Data'!N21 -> Yes
A23: ='1. Raw Data'!A22 -> EMP-0021 | B23: ='1. Raw Data'!B22 -> 31 | C23: ='1. Raw Data'!C22 -> Sales | D23: ='1. Raw Data'!D22 -> Mid | E23: ='1. Raw Data'!E22 -> Business | F23: ='1. Raw Data'!F22 -> 6.7 | G23: =IF('1. Raw Data'!G22="",ROUND(IFERROR(AVERAGEIFS('1. Raw Data'!G2:G1201,'1. Raw Data'!C2:C1201,'1. Raw Data'!C22,'1. Raw Data'!D2:D1201,'1. Raw Data'!D22),0),2),'1. Raw Data'!G22) -> 5483.59 | H23: =PROPER('1. Raw Data'!H22) -> Yes | I23: ='1. Raw Data'!I22 -> 3 | J23: ='1. Raw Data'!J22 -> 2 | K23: ='1. Raw Data'!K22 -> 11 | L23: ='1. Raw Data'!L22 -> 1 | M23: ='1. Raw Data'!M22 -> 2 | N23: ='1. Raw Data'!N22 -> No
A24: ='1. Raw Data'!A23 -> EMP-0022 | B24: ='1. Raw Data'!B23 -> 43 | C24: ='1. Raw Data'!C23 -> Marketing | D24: ='1. Raw Data'!D23 -> Junior | E24: ='1. Raw Data'!E23 -> Marketing | F24: ='1. Raw Data'!F23 -> 1.2 | G24: =IF('1. Raw Data'!G23="",ROUND(IFERROR(AVERAGEIFS('1. Raw Data'!G2:G1201,'1. Raw Data'!C2:C1201,'1. Raw Data'!C23,'1. Raw Data'!D2:D1201,'1. Raw Data'!D23),0),2),'1. Raw Data'!G23) -> 2759.51 | H24: =PROPER('1. Raw Data'!H23) -> No | I24: ='1. Raw Data'!I23 -> 3 | J24: ='1. Raw Data'!J23 -> 4 | K24: ='1. Raw Data'!K23 -> 7 | L24: ='1. Raw Data'!L23 -> 0 | M24: ='1. Raw Data'!M23 -> 1 | N24: ='1. Raw Data'!N23 -> Yes
A25: ='1. Raw Data'!A24 -> EMP-0023 | B25: ='1. Raw Data'!B24 -> 27 | C25: ='1. Raw Data'!C24 -> Engineering | D25: ='1. Raw Data'!D24 -> Mid | E25: ='1. Raw Data'!E24 -> Other | F25: ='1. Raw Data'!F24 -> 1.3 | G25: =IF('1. Raw Data'!G24="",ROUND(IFERROR(AVERAGEIFS('1. Raw Data'!G2:G1201,'1. Raw Data'!C2:C1201,'1. Raw Data'!C24,'1. Raw Data'!D2:D1201,'1. Raw Data'!D24),0),2),'1. Raw Data'!G24) -> 5552.57 | H25: =PROPER('1. Raw Data'!H24) -> No | I25: ='1. Raw Data'!I24 -> 4 | J25: ='1. Raw Data'!J24 -> 3 | K25: ='1. Raw Data'!K24 -> 3 | L25: ='1. Raw Data'!L24 -> 0 | M25: ='1. Raw Data'!M24 -> 2 | N25: ='1. Raw Data'!N24 -> No
A26: ='1. Raw Data'!A25 -> EMP-0024 | B26: ='1. Raw Data'!B25 -> 45 | C26: ='1. Raw Data'!C25 -> Customer Support | D26: ='1. Raw Data'!D25 -> Mid | E26: ='1. Raw Data'!E25 -> Business | F26: ='1. Raw Data'!F25 -> 1.1 | G26: =IF('1. Raw Data'!G25="",ROUND(IFERROR(AVERAGEIFS('1. Raw Data'!G2:G1201,'1. Raw Data'!C2:C1201,'1. Raw Data'!C25,'1. Raw Data'!D2:D1201,'1. Raw Data'!D25),0),2),'1. Raw Data'!G25) -> 5591.29 | H26: =PROPER('1. Raw Data'!H25) -> Yes | I26: ='1. Raw Data'!I25 -> 4 | J26: ='1. Raw Data'!J25 -> 2 | K26: ='1. Raw Data'!K25 -> 26 | L26: ='1. Raw Data'!L25 -> 1 | M26: ='1. Raw Data'!M25 -> 0 | N26: ='1. Raw Data'!N25 -> No
A27: ='1. Raw Data'!A26 -> EMP-0025 | B27: ='1. Raw Data'!B26 -> 44 | C27: ='1. Raw Data'!C26 -> Marketing | D27: ='1. Raw Data'!D26 -> Mid | E27: ='1. Raw Data'!E26 -> Business | F27: ='1. Raw Data'!F26 -> 2.2 | G27: =IF('1. Raw Data'!G26="",ROUND(IFERROR(AVERAGEIFS('1. Raw Data'!G2:G1201,'1. Raw Data'!C2:C1201,'1. Raw Data'!C26,'1. Raw Data'!D2:D1201,'1. Raw Data'!D26),0),2),'1. Raw Data'!G26) -> 4235.54 | H27: =PROPER('1. Raw Data'!H26) -> Yes | I27: ='1. Raw Data'!I26 -> 2 | J27: ='1. Raw Data'!J26 -> 2 | K27: ='1. Raw Data'!K26 -> 1 | L27: ='1. Raw Data'!L26 -> 0 | M27: ='1. Raw Data'!M26 -> 1 | N27: ='1. Raw Data'!N26 -> No
A28: ='1. Raw Data'!A27 -> EMP-0026 | B28: ='1. Raw Data'!B27 -> 27 | C28: ='1. Raw Data'!C27 -> Sales | D28: ='1. Raw Data'!D27 -> Senior | E28: ='1. Raw Data'!E27 -> Other | F28: ='1. Raw Data'!F27 -> 0.4 | G28: =IF('1. Raw Data'!G27="",ROUND(IFERROR(AVERAGEIFS('1. Raw Data'!G2:G1201,'1. Raw Data'!C2:C1201,'1. Raw Data'!C27,'1. Raw Data'!D2:D1201,'1. Raw Data'!D27),0),2),'1. Raw Data'!G27) -> 6661.27 | H28: =PROPER('1. Raw Data'!H27) -> No | I28: ='1. Raw Data'!I27 -> 4 | J28: ='1. Raw Data'!J27 -> 3 | K28: ='1. Raw Data'!K27 -> 1 | L28: ='1. Raw Data'!L27 -> 0 | M28: ='1. Raw Data'!M27 -> 0 | N28: ='1. Raw Data'!N27 -> No
A29: ='1. Raw Data'!A28 -> EMP-0027 | B29: ='1. Raw Data'!B28 -> 41 | C29: ='1. Raw Data'!C28 -> Engineering | D29: ='1. Raw Data'!D28 -> Mid | E29: ='1. Raw Data'!E28 -> Marketing | F29: ='1. Raw Data'!F28 -> 5.2 | G29: =IF('1. Raw Data'!G28="",ROUND(IFERROR(AVERAGEIFS('1. Raw Data'!G2:G1201,'1. Raw Data'!C2:C1201,'1. Raw Data'!C28,'1. Raw Data'!D2:D1201,'1. Raw Data'!D28),0),2),'1. Raw Data'!G28) -> 5103.77 | H29: =PROPER('1. Raw Data'!H28) -> No | I29: ='1. Raw Data'!I28 -> 4 | J29: ='1. Raw Data'!J28 -> 4 | K29: ='1. Raw Data'!K28 -> 16 | L29: ='1. Raw Data'!L28 -> 2 | M29: ='1. Raw Data'!M28 -> 0 | N29: ='1. Raw Data'!N28 -> No
A30: ='1. Raw Data'!A29 -> EMP-0028 | B30: ='1. Raw Data'!B29 -> 34 | C30: ='1. Raw Data'!C29 -> Sales | D30: ='1. Raw Data'!D29 -> Mid | E30: ='1. Raw Data'!E29 -> Technical | F30: ='1. Raw Data'!F29 -> 2 | G30: =IF('1. Raw Data'!G29="",ROUND(IFERROR(AVERAGEIFS('1. Raw Data'!G2:G1201,'1. Raw Data'!C2:C1201,'1. Raw Data'!C29,'1. Raw Data'!D2:D1201,'1. Raw Data'!D29),0),2),'1. Raw Data'!G29) -> 4928.49 | H30: =PROPER('1. Raw Data'!H29) -> No | I30: ='1. Raw Data'!I29 -> 2 | J30: ='1. Raw Data'!J29 -> 3 | K30: ='1. Raw Data'!K29 -> 3 | L30: ='1. Raw Data'!L29 -> 2 | M30: ='1. Raw Data'!M29 -> 1 | N30: ='1. Raw Data'!N29 -> Yes
A31: ='1. Raw Data'!A30 -> EMP-0029 | B31: ='1. Raw Data'!B30 -> 39 | C31: ='1. Raw Data'!C30 -> Customer Support | D31: ='1. Raw Data'!D30 -> Mid | E31: ='1. Raw Data'!E30 -> Technical | F31: ='1. Raw Data'!F30 -> 2.2 | G31: =IF('1. Raw Data'!G30="",ROUND(IFERROR(AVERAGEIFS('1. Raw Data'!G2:G1201,'1. Raw Data'!C2:C1201,'1. Raw Data'!C30,'1. Raw Data'!D2:D1201,'1. Raw Data'!D30),0),2),'1. Raw Data'!G30) -> 4145.58 | H31: =PROPER('1. Raw Data'!H30) -> No | I31: ='1. Raw Data'!I30 -> 1 | J31: ='1. Raw Data'!J30 -> 4 | K31: ='1. Raw Data'!K30 -> 1 | L31: ='1. Raw Data'!L30 -> 2 | M31: ='1. Raw Data'!M30 -> 1 | N31: ='1. Raw Data'!N30 -> No
A32: ='1. Raw Data'!A31 -> EMP-0030 | B32: ='1. Raw Data'!B31 -> 31 | C32: ='1. Raw Data'!C31 -> Finance | D32: ='1. Raw Data'!D31 -> Junior | E32: ='1. Raw Data'!E31 -> Technical | F32: ='1. Raw Data'!F31 -> 2 | G32: =IF('1. Raw Data'!G31="",ROUND(IFERROR(AVERAGEIFS('1. Raw Data'!G2:G1201,'1. Raw Data'!C2:C1201,'1. Raw Data'!C31,'1. Raw Data'!D2:D1201,'1. Raw Data'!D31),0),2),'1. Raw Data'!G31) -> 3456.32 | H32: =PROPER('1. Raw Data'!H31) -> No | I32: ='1. Raw Data'!I31 -> 1 | J32: ='1. Raw Data'!J31 -> 4 | K32: ='1. Raw Data'!K31 -> 19 | L32: ='1. Raw Data'!L31 -> 0 | M32: ='1. Raw Data'!M31 -> 2 | N32: ='1. Raw Data'!N31 -> Yes
A33: ='1. Raw Data'!A32 -> EMP-0031 | B33: ='1. Raw Data'!B32 -> 45 | C33: ='1. Raw Data'!C32 -> Engineering | D33: ='1. Raw Data'!D32 -> Senior | E33: ='1. Raw Data'!E32 -> Other | F33: ='1. Raw Data'!F32 -> 4 | G33: =IF('1. Raw Data'!G32="",ROUND(IFERROR(AVERAGEIFS('1. Raw Data'!G2:G1201,'1. Raw Data'!C2:C1201,'1. Raw Data'!C32,'1. Raw Data'!D2:D1201,'1. Raw Data'!D32),0),2),'1. Raw Data'!G32) -> 6392.62 | H33: =PROPER('1. Raw Data'!H32) -> No | I33: ='1. Raw Data'!I32 -> 2 | J33: ='1. Raw Data'!J32 -> 4 | K33: ='1. Raw Data'!K32 -> 5 | L33: ='1. Raw Data'!L32 -> 0 | M33: ='1. Raw Data'!M32 -> 4 | N33: ='1. Raw Data'!N32 -> Yes
A34: ='1. Raw Data'!A33 -> EMP-0032 | B34: ='1. Raw Data'!B33 -> 34 | C34: ='1. Raw Data'!C33 -> Sales | D34: ='1. Raw Data'!D33 -> Mid | E34: ='1. Raw Data'!E33 -> Marketing | F34: ='1. Raw Data'!F33 -> 0.5 | G34: =IF('1. Raw Data'!G33="",ROUND(IFERROR(AVERAGEIFS('1. Raw Data'!G2:G1201,'1. Raw Data'!C2:C1201,'1. Raw Data'!C33,'1. Raw Data'!D2:D1201,'1. Raw Data'!D33),0),2),'1. Raw Data'!G33) -> 4986.2 | H34: =PROPER('1. Raw Data'!H33) -> Yes | I34: ='1. Raw Data'!I33 -> 3 | J34: ='1. Raw Data'!J33 -> 3 | K34: ='1. Raw Data'!K33 -> 2 | L34: ='1. Raw Data'!L33 -> 0 | M34: ='1. Raw Data'!M33 -> 1 | N34: ='1. Raw Data'!N33 -> No
A35: ='1. Raw Data'!A34 -> EMP-0033 | B35: ='1. Raw Data'!B34 -> 45 | C35: ='1. Raw Data'!C34 -> Marketing | D35: ='1. Raw Data'!D34 -> Senior | E35: ='1. Raw Data'!E34 -> Marketing | F35: ='1. Raw Data'!F34 -> 1 | G35: =IF('1. Raw Data'!G34="",ROUND(IFERROR(AVERAGEIFS('1. Raw Data'!G2:G1201,'1. Raw Data'!C2:C1201,'1. Raw Data'!C34,'1. Raw Data'!D2:D1201,'1. Raw Data'!D34),0),2),'1. Raw Data'!G34) -> 7306.64 | H35: =PROPER('1. Raw Data'!H34) -> No | I35: ='1. Raw Data'!I34 -> 3 | J35: ='1. Raw Data'!J34 -> 3 | K35: ='1. Raw Data'!K34 -> 14 | L35: ='1. Raw Data'!L34 -> 0 | M35: ='1. Raw Data'!M34 -> 4 | N35: ='1. Raw Data'!N34 -> No
A36: ='1. Raw Data'!A35 -> EMP-0034 | B36: ='1. Raw Data'!B35 -> 44 | C36: ='1. Raw Data'!C35 -> HR | D36: ='1. Raw Data'!D35 -> Lead | E36: ='1. Raw Data'!E35 -> Other | F36: ='1. Raw Data'!F35 -> 1 | G36: =IF('1. Raw Data'!G35="",ROUND(IFERROR(AVERAGEIFS('1. Raw Data'!G2:G1201,'1. Raw Data'!C2:C1201,'1. Raw Data'!C35,'1. Raw Data'!D2:D1201,'1. Raw Data'!D35),0),2),'1. Raw Data'!G35) -> 11157.97 | H36: =PROPER('1. Raw Data'!H35) -> No | I36: ='1. Raw Data'!I35 -> 2 | J36: ='1. Raw Data'!J35 -> 3 | K36: ='1. Raw Data'!K35 -> 18 | L36: ='1. Raw Data'!L35 -> 1 | M36: ='1. Raw Data'!M35 -> 2 | N36: ='1. Raw Data'!N35 -> No
A37: ='1. Raw Data'!A36 -> EMP-0035 | B37: ='1. Raw Data'!B36 -> 30 | C37: ='1. Raw Data'!C36 -> Marketing | D37: ='1. Raw Data'!D36 -> Junior | E37: ='1. Raw Data'!E36 -> Technical | F37: ='1. Raw Data'!F36 -> 1.3 | G37: =IF('1. Raw Data'!G36="",ROUND(IFERROR(AVERAGEIFS('1. Raw Data'!G2:G1201,'1. Raw Data'!C2:C1201,'1. Raw Data'!C36,'1. Raw Data'!D2:D1201,'1. Raw Data'!D36),0),2),'1. Raw Data'!G36) -> 3357.91 | H37: =PROPER('1. Raw Data'!H36) -> No | I37: ='1. Raw Data'!I36 -> 4 | J37: ='1. Raw Data'!J36 -> 4 | K37: ='1. Raw Data'!K36 -> 2 | L37: ='1. Raw Data'!L36 -> 0 | M37: ='1. Raw Data'!M36 -> 3 | N37: ='1. Raw Data'!N36 -> No
A38: ='1. Raw Data'!A37 -> EMP-0036 | B38: ='1. Raw Data'!B37 -> 38 | C38: ='1. Raw Data'!C37 -> Sales | D38: ='1. Raw Data'!D37 -> Mid | E38: ='1. Raw Data'!E37 -> Business | F38: ='1. Raw Data'!F37 -> 7.6 | G38: =IF('1. Raw Data'!G37="",ROUND(IFERROR(AVERAGEIFS('1. Raw Data'!G2:G1201,'1. Raw Data'!C2:C1201,'1. Raw Data'!C37,'1. Raw Data'!D2:D1201,'1. Raw Data'!D37),0),2),'1. Raw Data'!G37) -> 5617.54 | H38: =PROPER('1. Raw Data'!H37) -> No | I38: ='1. Raw Data'!I37 -> 4 | J38: ='1. Raw Data'!J37 -> 4 | K38: ='1. Raw Data'!K37 -> 1 | L38: ='1. Raw Data'!L37 -> 4 | M38: ='1. Raw Data'!M37 -> 1 | N38: ='1. Raw Data'!N37 -> No
A39: ='1. Raw Data'!A38 -> EMP-0037 | B39: ='1. Raw Data'!B38 -> 34 | C39: ='1. Raw Data'!C38 -> Customer Support | D39: ='1. Raw Data'!D38 -> Mid | E39: ='1. Raw Data'!E38 -> Marketing | F39: ='1. Raw Data'!F38 -> 1.3 | G39: =IF('1. Raw Data'!G38="",ROUND(IFERROR(AVERAGEIFS('1. Raw Data'!G2:G1201,'1. Raw Data'!C2:C1201,'1. Raw Data'!C38,'1. Raw Data'!D2:D1201,'1. Raw Data'!D38),0),2),'1. Raw Data'!G38) -> 4708.58 | H39: =PROPER('1. Raw Data'!H38) -> No | I39: ='1. Raw Data'!I38 -> 4 | J39: ='1. Raw Data'!J38 -> 2 | K39: ='1. Raw Data'!K38 -> 2 | L39: ='1. Raw Data'!L38 -> 0 | M39: ='1. Raw Data'!M38 -> 1 | N39: ='1. Raw Data'!N38 -> Yes
A40: ='1. Raw Data'!A39 -> EMP-0038 | B40: ='1. Raw Data'!B39 -> 38 | C40: ='1. Raw Data'!C39 -> Engineering | D40: ='1. Raw Data'!D39 -> Junior | E40: ='1. Raw Data'!E39 -> Marketing | F40: ='1. Raw Data'!F39 -> 2.6 | G40: =IF('1. Raw Data'!G39="",ROUND(IFERROR(AVERAGEIFS('1. Raw Data'!G2:G1201,'1. Raw Data'!C2:C1201,'1. Raw Data'!C39,'1. Raw Data'!D2:D1201,'1. Raw Data'!D39),0),2),'1. Raw Data'!G39) -> 3768.35 | H40: =PROPER('1. Raw Data'!H39) -> No | I40: ='1. Raw Data'!I39 -> 1 | J40: ='1. Raw Data'!J39 -> 2 | K40: ='1. Raw Data'!K39 -> 4 | L40: ='1. Raw Data'!L39 -> 2 | M40: ='1. Raw Data'!M39 -> 1 | N40: ='1. Raw Data'!N39 -> No
...

Sheet 3. Attrition Summary
A1: HR Attrition Analysis — Summary (built from Cleaned Data tab)
A3: Attrition Rate by Department
A4: Department | B4: Headcount | C4: Leavers | D4: Attrition Rate | E4: Avg Tenure (yrs) | F4: Avg Monthly Income
A5: Customer Support | B5: =COUNTIF('2. Cleaned Data'!C3:C1202,A5) -> 247 | C5: =COUNTIFS('2. Cleaned Data'!C3:C1202,A5,'2. Cleaned Data'!N3:N1202,"Yes") -> 97 | D5: =IFERROR(C5/B5,0) -> 0.39271255 | E5: =IFERROR(AVERAGEIF('2. Cleaned Data'!C3:C1202,A5,'2. Cleaned Data'!F3:F1202),0) -> 2.5987854 | F5: =IFERROR(AVERAGEIF('2. Cleaned Data'!C3:C1202,A5,'2. Cleaned Data'!G3:G1202),0) -> 5143.6565
A6: Engineering | B6: =COUNTIF('2. Cleaned Data'!C3:C1202,A6) -> 271 | C6: =COUNTIFS('2. Cleaned Data'!C3:C1202,A6,'2. Cleaned Data'!N3:N1202,"Yes") -> 61 | D6: =IFERROR(C6/B6,0) -> 0.22509225 | E6: =IFERROR(AVERAGEIF('2. Cleaned Data'!C3:C1202,A6,'2. Cleaned Data'!F3:F1202),0) -> 2.4811808 | F6: =IFERROR(AVERAGEIF('2. Cleaned Data'!C3:C1202,A6,'2. Cleaned Data'!G3:G1202),0) -> 5095.5478
A7: Finance | B7: =COUNTIF('2. Cleaned Data'!C3:C1202,A7) -> 141 | C7: =COUNTIFS('2. Cleaned Data'!C3:C1202,A7,'2. Cleaned Data'!N3:N1202,"Yes") -> 30 | D7: =IFERROR(C7/B7,0) -> 0.21276596 | E7: =IFERROR(AVERAGEIF('2. Cleaned Data'!C3:C1202,A7,'2. Cleaned Data'!F3:F1202),0) -> 2.7333333 | F7: =IFERROR(AVERAGEIF('2. Cleaned Data'!C3:C1202,A7,'2. Cleaned Data'!G3:G1202),0) -> 5037.7382
A8: HR | B8: =COUNTIF('2. Cleaned Data'!C3:C1202,A8) -> 96 | C8: =COUNTIFS('2. Cleaned Data'!C3:C1202,A8,'2. Cleaned Data'!N3:N1202,"Yes") -> 20 | D8: =IFERROR(C8/B8,0) -> 0.20833333 | E8: =IFERROR(AVERAGEIF('2. Cleaned Data'!C3:C1202,A8,'2. Cleaned Data'!F3:F1202),0) -> 2.8895833 | F8: =IFERROR(AVERAGEIF('2. Cleaned Data'!C3:C1202,A8,'2. Cleaned Data'!G3:G1202),0) -> 5137.4895
A9: Marketing | B9: =COUNTIF('2. Cleaned Data'!C3:C1202,A9) -> 150 | C9: =COUNTIFS('2. Cleaned Data'!C3:C1202,A9,'2. Cleaned Data'!N3:N1202,"Yes") -> 28 | D9: =IFERROR(C9/B9,0) -> 0.18666667 | E9: =IFERROR(AVERAGEIF('2. Cleaned Data'!C3:C1202,A9,'2. Cleaned Data'!F3:F1202),0) -> 2.438 | F9: =IFERROR(AVERAGEIF('2. Cleaned Data'!C3:C1202,A9,'2. Cleaned Data'!G3:G1202),0) -> 5263.1728
A10: Sales | B10: =COUNTIF('2. Cleaned Data'!C3:C1202,A10) -> 295 | C10: =COUNTIFS('2. Cleaned Data'!C3:C1202,A10,'2. Cleaned Data'!N3:N1202,"Yes") -> 64 | D10: =IFERROR(C10/B10,0) -> 0.21694915 | E10: =IFERROR(AVERAGEIF('2. Cleaned Data'!C3:C1202,A10,'2. Cleaned Data'!F3:F1202),0) -> 2.5535593 | F10: =IFERROR(AVERAGEIF('2. Cleaned Data'!C3:C1202,A10,'2. Cleaned Data'!G3:G1202),0) -> 5272.0484
A11: Company-wide | B11: =SUM(B5:B10) -> 1200 | C11: =SUM(C5:C10) -> 300 | D11: =IFERROR(C11/B11,0) -> 0.25
A13: Attrition Rate by Overtime
A14: Value | B14: Headcount | C14: Leavers | D14: Attrition Rate
A15: Yes | B15: =COUNTIF('2. Cleaned Data'!H3:H1202,A15) -> 407 | C15: =COUNTIFS('2. Cleaned Data'!H3:H1202,A15,'2. Cleaned Data'!N3:N1202,"Yes") -> 144 | D15: =IFERROR(C15/B15,0) -> 0.35380835
A16: No | B16: =COUNTIF('2. Cleaned Data'!H3:H1202,A16) -> 793 | C16: =COUNTIFS('2. Cleaned Data'!H3:H1202,A16,'2. Cleaned Data'!N3:N1202,"Yes") -> 156 | D16: =IFERROR(C16/B16,0) -> 0.19672131
A18: Attrition Rate by Job Satisfaction (1=Low, 4=Very High)
A19: Value | B19: Headcount | C19: Leavers | D19: Attrition Rate
A20: 1 | B20: =COUNTIF('2. Cleaned Data'!I3:I1202,A20) -> 164 | C20: =COUNTIFS('2. Cleaned Data'!I3:I1202,A20,'2. Cleaned Data'!N3:N1202,"Yes") -> 61 | D20: =IFERROR(C20/B20,0) -> 0.37195122
A21: 2 | B21: =COUNTIF('2. Cleaned Data'!I3:I1202,A21) -> 232 | C21: =COUNTIFS('2. Cleaned Data'!I3:I1202,A21,'2. Cleaned Data'!N3:N1202,"Yes") -> 84 | D21: =IFERROR(C21/B21,0) -> 0.36206897
A22: 3 | B22: =COUNTIF('2. Cleaned Data'!I3:I1202,A22) -> 440 | C22: =COUNTIFS('2. Cleaned Data'!I3:I1202,A22,'2. Cleaned Data'!N3:N1202,"Yes") -> 73 | D22: =IFERROR(C22/B22,0) -> 0.16590909
A23: 4 | B23: =COUNTIF('2. Cleaned Data'!I3:I1202,A23) -> 364 | C23: =COUNTIFS('2. Cleaned Data'!I3:I1202,A23,'2. Cleaned Data'!N3:N1202,"Yes") -> 82 | D23: =IFERROR(C23/B23,0) -> 0.22527473
A25: Attrition Rate by Work-Life Balance (1=Bad, 4=Best)
A26: Value | B26: Headcount | C26: Leavers | D26: Attrition Rate
A27: 1 | B27: =COUNTIF('2. Cleaned Data'!J3:J1202,A27) -> 132 | C27: =COUNTIFS('2. Cleaned Data'!J3:J1202,A27,'2. Cleaned Data'!N3:N1202,"Yes") -> 51 | D27: =IFERROR(C27/B27,0) -> 0.38636364
A28: 2 | B28: =COUNTIF('2. Cleaned Data'!J3:J1202,A28) -> 290 | C28: =COUNTIFS('2. Cleaned Data'!J3:J1202,A28,'2. Cleaned Data'!N3:N1202,"Yes") -> 96 | D28: =IFERROR(C28/B28,0) -> 0.33103448
A29: 3 | B29: =COUNTIF('2. Cleaned Data'!J3:J1202,A29) -> 454 | C29: =COUNTIFS('2. Cleaned Data'!J3:J1202,A29,'2. Cleaned Data'!N3:N1202,"Yes") -> 90 | D29: =IFERROR(C29/B29,0) -> 0.19823789
A30: 4 | B30: =COUNTIF('2. Cleaned Data'!J3:J1202,A30) -> 324 | C30: =COUNTIFS('2. Cleaned Data'!J3:J1202,A30,'2. Cleaned Data'!N3:N1202,"Yes") -> 63 | D30: =IFERROR(C30/B30,0) -> 0.19444444

Sheet 4. Insights
A1: Key Insights
A3: 1. Customer Support has the highest attrition rate at 39.3%, nearly double the company-wide rate and well above every other department.
A4: 2. Employees working overtime leave at 35.4%, vs 19.7% for those who don't - the single strongest driver in the dataset.
A5: 3. Low job satisfaction (score 1-2) correlates with ~37% attrition, vs ~19% for scores 3-4.
A6: 4. Within Customer Support specifically, employees on overtime AND with low satisfaction leave at the highest rate of any segment (47.7%).
A7: 5. Recommendation: prioritize a retention intervention (workload review, overtime caps, or a pay/role review) for Customer Support staff currently working overtime, since this segment drives a disproportionate share of total attrition.
